Workbook

Sheet employees_cleaned
A1: employee_id | B1: gender | C1: age | D1: education | E1: department | F1: job_role | G1: hire_date | H1: manager_id | I1: location | J1: employment_type | K1: attrition_flag | L1: exit_date | M1: salary | N1: bonus | O1: salary_band | P1: avg_engagement_score | Q1: engagement_response_flag | R1: tenure_months | S1: tenure_bucket | T1: avg_performance_rating | U1: avg_band_salary | V1: salary_position | W1: performance_level | X1: pay_performance_index | Y1: pay_performance_index
A2: E100000 | B2: F | C2: 42 | D2: Graduate | E2: Finance | F2: Financial Analyst | G2: 44030 | H2: M274 | I2: Pune | J2: Contract | K2: =_xlfn.XLOOKUP(A2,attrition_cleaned!$A:$A,attrition_cleaned!$B:$B,"Missing") -> No | M2: =_xlfn.XLOOKUP(A2,compensation_cleaned!$A:$A,compensation_cleaned!$B:$B,"Missing") -> 417763 | N2: =_xlfn.XLOOKUP(A2,compensation_cleaned!$A:$A,compensation_cleaned!$C:$C,"Missing") -> 45322 | O2: =_xlfn.XLOOKUP(A2,compensation_cleaned!$A:$A,compensation_cleaned!$D:$D,"Missing") -> L1 | P2: =_xlfn.XLOOKUP(A2,engagement_pivot!$A:$A,engagement_pivot!$B:$B,"Missing") -> 2.3333333 | Q2: =IF( _xlfn.XLOOKUP(A2, engagement_pivot!A:A, engagement_pivot!C:C, 0) > 0, "Yes", "No" ) -> Yes | R2: =IF(K2="Yes",DATEDIF(G2,L2,"M"),DATEDIF(G2,DATE(2023,12,31),"M")) -> 41 | S2: =IF(R2<=12,"0–12 months", IF(R2<=36,"13–36 months","37+ months")) -> 37+ months | T2: =_xlfn.XLOOKUP(A2,performance_pivot!$A:$A,performance_pivot!$B:$B,"Missing") -> 4 | U2: =_xlfn.XLOOKUP(A2,compensation_cleaned!$A:$A,compensation_cleaned!$F:$F,"Missing") -> 499723.04 | V2: =IF(M2>U2,"Above Avg Pay","Below Avg Pay") -> Below Avg Pay | W2: =IF(T2>=4,"High Performer","Low/Avg Performer") -> High Performer | Y2: =IF( AND(V2="Above Avg Pay",W2="High Performer"),"Well Aligned", IF( AND(V2="Below Avg Pay",W2="High Performer"),"Underpaid High Performer", IF( AND(V2="Above Avg Pay",W2="Low/Avg Performer"),"Overpaid Low Performer", "Low Pay & Low Performance" ) ) ) -> Underpaid High Performer | AE2: Total
A3: E100001 | B3: M | C3: 23 | D3: Postgraduate | E3: Finance | F3: Accountant | G3: 42866 | H3: M237 | I3: Hyderabad | J3: Full-time | K3: =_xlfn.XLOOKUP(A3,attrition_cleaned!$A:$A,attrition_cleaned!$B:$B,"Missing") -> No | M3: =_xlfn.XLOOKUP(A3,compensation_cleaned!$A:$A,compensation_cleaned!$B:$B,"Missing") -> 1114335 | N3: =_xlfn.XLOOKUP(A3,compensation_cleaned!$A:$A,compensation_cleaned!$C:$C,"Missing") -> 92842 | O3: =_xlfn.XLOOKUP(A3,compensation_cleaned!$A:$A,compensation_cleaned!$D:$D,"Missing") -> L3 | P3: =_xlfn.XLOOKUP(A3,engagement_pivot!$A:$A,engagement_pivot!$B:$B,"Missing") -> 2.6666667 | Q3: =IF( _xlfn.XLOOKUP(A3, engagement_pivot!A:A, engagement_pivot!C:C, 0) > 0, "Yes", "No" ) -> Yes | R3: =IF(K3="Yes",DATEDIF(G3,L3,"M"),DATEDIF(G3,DATE(2023,12,31),"M")) -> 79 | S3: =IF(R3<=12,"0–12 months", IF(R3<=36,"13–36 months","37+ months")) -> 37+ months | T3: =_xlfn.XLOOKUP(A3,performance_pivot!$A:$A,performance_pivot!$B:$B,"Missing") -> 3.25 | U3: =_xlfn.XLOOKUP(A3,compensation_cleaned!$A:$A,compensation_cleaned!$F:$F,"Missing") -> 1044648.5 | V3: =IF(M3>U3,"Above Avg Pay","Below Avg Pay") -> Above Avg Pay | W3: =IF(T3>=4,"High Performer","Low/Avg Performer") -> Low/Avg Performer | Y3: =IF( AND(V3="Above Avg Pay",W3="High Performer"),"Well Aligned", IF( AND(V3="Below Avg Pay",W3="High Performer"),"Underpaid High Performer", IF( AND(V3="Above Avg Pay",W3="Low/Avg Performer"),"Overpaid Low Performer", "Low Pay & Low Performance" ) ) ) -> Overpaid Low Performer | AD3: High Tenure | AE3: =COUNTIF(S:S,"37+ months") -> 1679
A4: E100002 | B4: M | C4: 33 | D4: Graduate | E4: Operations | F4: Operations Analyst | G4: 43195 | H4: M258 | I4: Hyderabad | J4: Full-time | K4: =_xlfn.XLOOKUP(A4,attrition_cleaned!$A:$A,attrition_cleaned!$B:$B,"Missing") -> No | M4: =_xlfn.XLOOKUP(A4,compensation_cleaned!$A:$A,compensation_cleaned!$B:$B,"Missing") -> 819575 | N4: =_xlfn.XLOOKUP(A4,compensation_cleaned!$A:$A,compensation_cleaned!$C:$C,"Missing") -> 70960 | O4: =_xlfn.XLOOKUP(A4,compensation_cleaned!$A:$A,compensation_cleaned!$D:$D,"Missing") -> L2 | P4: =_xlfn.XLOOKUP(A4,engagement_pivot!$A:$A,engagement_pivot!$B:$B,"Missing") -> 2 | Q4: =IF( _xlfn.XLOOKUP(A4, engagement_pivot!A:A, engagement_pivot!C:C, 0) > 0, "Yes", "No" ) -> Yes | R4: =IF(K4="Yes",DATEDIF(G4,L4,"M"),DATEDIF(G4,DATE(2023,12,31),"M")) -> 68 | S4: =IF(R4<=12,"0–12 months", IF(R4<=36,"13–36 months","37+ months")) -> 37+ months | T4: =_xlfn.XLOOKUP(A4,performance_pivot!$A:$A,performance_pivot!$B:$B,"Missing") -> 3 | U4: =_xlfn.XLOOKUP(A4,compensation_cleaned!$A:$A,compensation_cleaned!$F:$F,"Missing") -> 746435.4 | V4: =IF(M4>U4,"Above Avg Pay","Below Avg Pay") -> Above Avg Pay | W4: =IF(T4>=4,"High Performer","Low/Avg Performer") -> Low/Avg Performer | Y4: =IF( AND(V4="Above Avg Pay",W4="High Performer"),"Well Aligned", IF( AND(V4="Below Avg Pay",W4="High Performer"),"Underpaid High Performer", IF( AND(V4="Above Avg Pay",W4="Low/Avg Performer"),"Overpaid Low Performer", "Low Pay & Low Performance" ) ) ) -> Overpaid Low Performer | AD4: Mid Tenure | AE4: =COUNTIF(S:S,"13–36 months") -> 1048
A5: E100003 | B5: M | C5: 36 | D5: Graduate | E5: Finance | F5: Accountant | G5: 44542 | H5: M307 | I5: Delhi | J5: Full-time | K5: =_xlfn.XLOOKUP(A5,attrition_cleaned!$A:$A,attrition_cleaned!$B:$B,"Missing") -> No | M5: =_xlfn.XLOOKUP(A5,compensation_cleaned!$A:$A,compensation_cleaned!$B:$B,"Missing") -> 485874 | N5: =_xlfn.XLOOKUP(A5,compensation_cleaned!$A:$A,compensation_cleaned!$C:$C,"Missing") -> 29469 | O5: =_xlfn.XLOOKUP(A5,compensation_cleaned!$A:$A,compensation_cleaned!$D:$D,"Missing") -> L1 | P5: =_xlfn.XLOOKUP(A5,engagement_pivot!$A:$A,engagement_pivot!$B:$B,"Missing") -> 2 | Q5: =IF( _xlfn.XLOOKUP(A5, engagement_pivot!A:A, engagement_pivot!C:C, 0) > 0, "Yes", "No" ) -> Yes | R5: =IF(K5="Yes",DATEDIF(G5,L5,"M"),DATEDIF(G5,DATE(2023,12,31),"M")) -> 24 | S5: =IF(R5<=12,"0–12 months", IF(R5<=36,"13–36 months","37+ months")) -> 13–36 months | T5: =_xlfn.XLOOKUP(A5,performance_pivot!$A:$A,performance_pivot!$B:$B,"Missing") -> 4.25 | U5: =_xlfn.XLOOKUP(A5,compensation_cleaned!$A:$A,compensation_cleaned!$F:$F,"Missing") -> 499723.04 | V5: =IF(M5>U5,"Above Avg Pay","Below Avg Pay") -> Below Avg Pay | W5: =IF(T5>=4,"High Performer","Low/Avg Performer") -> High Performer | Y5: =IF( AND(V5="Above Avg Pay",W5="High Performer"),"Well Aligned", IF( AND(V5="Below Avg Pay",W5="High Performer"),"Underpaid High Performer", IF( AND(V5="Above Avg Pay",W5="Low/Avg Performer"),"Overpaid Low Performer", "Low Pay & Low Performance" ) ) ) -> Underpaid High Performer | AD5: Low Tenure | AE5: =COUNTIF(S:S,"0–12 months") -> 473
A6: E100004 | B6: M | C6: 28 | D6: Graduate | E6: Sales | F6: Sales Executive | G6: 43382 | H6: M288 | I6: Delhi | J6: Full-time | K6: =_xlfn.XLOOKUP(A6,attrition_cleaned!$A:$A,attrition_cleaned!$B:$B,"Missing") -> No | M6: =_xlfn.XLOOKUP(A6,compensation_cleaned!$A:$A,compensation_cleaned!$B:$B,"Missing") -> 825704 | N6: =_xlfn.XLOOKUP(A6,compensation_cleaned!$A:$A,compensation_cleaned!$C:$C,"Missing") -> 45542 | O6: =_xlfn.XLOOKUP(A6,compensation_cleaned!$A:$A,compensation_cleaned!$D:$D,"Missing") -> L2 | P6: =_xlfn.XLOOKUP(A6,engagement_pivot!$A:$A,engagement_pivot!$B:$B,"Missing") -> 1.6666667 | Q6: =IF( _xlfn.XLOOKUP(A6, engagement_pivot!A:A, engagement_pivot!C:C, 0) > 0, "Yes", "No" ) -> Yes | R6: =IF(K6="Yes",DATEDIF(G6,L6,"M"),DATEDIF(G6,DATE(2023,12,31),"M")) -> 62 | S6: =IF(R6<=12,"0–12 months", IF(R6<=36,"13–36 months","37+ months")) -> 37+ months | T6: =_xlfn.XLOOKUP(A6,performance_pivot!$A:$A,performance_pivot!$B:$B,"Missing") -> 4 | U6: =_xlfn.XLOOKUP(A6,compensation_cleaned!$A:$A,compensation_cleaned!$F:$F,"Missing") -> 746435.4 | V6: =IF(M6>U6,"Above Avg Pay","Below Avg Pay") -> Above Avg Pay | W6: =IF(T6>=4,"High Performer","Low/Avg Performer") -> High Performer | Y6: =IF( AND(V6="Above Avg Pay",W6="High Performer"),"Well Aligned", IF( AND(V6="Below Avg Pay",W6="High Performer"),"Underpaid High Performer", IF( AND(V6="Above Avg Pay",W6="Low/Avg Performer"),"Overpaid Low Performer", "Low Pay & Low Performance" ) ) ) -> Well Aligned
A7: E100005 | B7: M | C7: 28 | D7: Graduate | E7: HR | F7: HR Executive | G7: 44099 | H7: M207 | I7: Pune | J7: Contract | K7: =_xlfn.XLOOKUP(A7,attrition_cleaned!$A:$A,attrition_cleaned!$B:$B,"Missing") -> No | M7: =_xlfn.XLOOKUP(A7,compensation_cleaned!$A:$A,compensation_cleaned!$B:$B,"Missing") -> 851431 | N7: =_xlfn.XLOOKUP(A7,compensation_cleaned!$A:$A,compensation_cleaned!$C:$C,"Missing") -> 110027 | O7: =_xlfn.XLOOKUP(A7,compensation_cleaned!$A:$A,compensation_cleaned!$D:$D,"Missing") -> L2 | P7: =_xlfn.XLOOKUP(A7,engagement_pivot!$A:$A,engagement_pivot!$B:$B,"Missing") -> 4 | Q7: =IF( _xlfn.XLOOKUP(A7, engagement_pivot!A:A, engagement_pivot!C:C, 0) > 0, "Yes", "No" ) -> Yes | R7: =IF(K7="Yes",DATEDIF(G7,L7,"M"),DATEDIF(G7,DATE(2023,12,31),"M")) -> 39 | S7: =IF(R7<=12,"0–12 months", IF(R7<=36,"13–36 months","37+ months")) -> 37+ months | T7: =_xlfn.XLOOKUP(A7,performance_pivot!$A:$A,performance_pivot!$B:$B,"Missing") -> 4.5 | U7: =_xlfn.XLOOKUP(A7,compensation_cleaned!$A:$A,compensation_cleaned!$F:$F,"Missing") -> 746435.4 | V7: =IF(M7>U7,"Above Avg Pay","Below Avg Pay") -> Above Avg Pay | W7: =IF(T7>=4,"High Performer","Low/Avg Performer") -> High Performer | Y7: =IF( AND(V7="Above Avg Pay",W7="High Performer"),"Well Aligned", IF( AND(V7="Below Avg Pay",W7="High Performer"),"Underpaid High Performer", IF( AND(V7="Above Avg Pay",W7="Low/Avg Performer"),"Overpaid Low Performer", "Low Pay & Low Performance" ) ) ) -> Well Aligned | AE7: Total
A8: E100006 | B8: M | C8: 31 | D8: Graduate | E8: Finance | F8: Accountant | G8: 43757 | H8: M345 | I8: Hyderabad | J8: Full-time | K8: =_xlfn.XLOOKUP(A8,attrition_cleaned!$A:$A,attrition_cleaned!$B:$B,"Missing") -> No | M8: =_xlfn.XLOOKUP(A8,compensation_cleaned!$A:$A,compensation_cleaned!$B:$B,"Missing") -> 660855 | N8: =_xlfn.XLOOKUP(A8,compensation_cleaned!$A:$A,compensation_cleaned!$C:$C,"Missing") -> 53466 | O8: =_xlfn.XLOOKUP(A8,compensation_cleaned!$A:$A,compensation_cleaned!$D:$D,"Missing") -> L2 | P8: =_xlfn.XLOOKUP(A8,engagement_pivot!$A:$A,engagement_pivot!$B:$B,"Missing") -> 5 | Q8: =IF( _xlfn.XLOOKUP(A8, engagement_pivot!A:A, engagement_pivot!C:C, 0) > 0, "Yes", "No" ) -> Yes | R8: =IF(K8="Yes",DATEDIF(G8,L8,"M"),DATEDIF(G8,DATE(2023,12,31),"M")) -> 50 | S8: =IF(R8<=12,"0–12 months", IF(R8<=36,"13–36 months","37+ months")) -> 37+ months | T8: =_xlfn.XLOOKUP(A8,performance_pivot!$A:$A,performance_pivot!$B:$B,"Missing") -> 4 | U8: =_xlfn.XLOOKUP(A8,compensation_cleaned!$A:$A,compensation_cleaned!$F:$F,"Missing") -> 746435.4 | V8: =IF(M8>U8,"Above Avg Pay","Below Avg Pay") -> Below Avg Pay | W8: =IF(T8>=4,"High Performer","Low/Avg Performer") -> High Performer | Y8: =IF( AND(V8="Above Avg Pay",W8="High Performer"),"Well Aligned", IF( AND(V8="Below Avg Pay",W8="High Performer"),"Underpaid High Performer", IF( AND(V8="Above Avg Pay",W8="Low/Avg Performer"),"Overpaid Low Performer", "Low Pay & Low Performance" ) ) ) -> Underpaid High Performer | AD8: Well Aligned | AE8: =COUNTIF(Y:Y,"Well Aligned") -> 622
A9: E100007 | B9: M | C9: 37 | D9: Graduate | E9: HR | F9: HR Business Partner | G9: 43731 | H9: M239 | I9: Mumbai | J9: Full-time | K9: =_xlfn.XLOOKUP(A9,attrition_cleaned!$A:$A,attrition_cleaned!$B:$B,"Missing") -> No | M9: =_xlfn.XLOOKUP(A9,compensation_cleaned!$A:$A,compensation_cleaned!$B:$B,"Missing") -> 1541591 | N9: =_xlfn.XLOOKUP(A9,compensation_cleaned!$A:$A,compensation_cleaned!$C:$C,"Missing") -> 167329 | O9: =_xlfn.XLOOKUP(A9,compensation_cleaned!$A:$A,compensation_cleaned!$D:$D,"Missing") -> L4 | P9: =_xlfn.XLOOKUP(A9,engagement_pivot!$A:$A,engagement_pivot!$B:$B,"Missing") -> 2 | Q9: =IF( _xlfn.XLOOKUP(A9, engagement_pivot!A:A, engagement_pivot!C:C, 0) > 0, "Yes", "No" ) -> Yes | R9: =IF(K9="Yes",DATEDIF(G9,L9,"M"),DATEDIF(G9,DATE(2023,12,31),"M")) -> 51 | S9: =IF(R9<=12,"0–12 months", IF(R9<=36,"13–36 months","37+ months")) -> 37+ months | T9: =_xlfn.XLOOKUP(A9,performance_pivot!$A:$A,performance_pivot!$B:$B,"Missing") -> 4 | U9: =_xlfn.XLOOKUP(A9,compensation_cleaned!$A:$A,compensation_cleaned!$F:$F,"Missing") -> 1044648.5 | V9: =IF(M9>U9,"Above Avg Pay","Below Avg Pay") -> Above Avg Pay | W9: =IF(T9>=4,"High Performer","Low/Avg Performer") -> High Performer | Y9: =IF( AND(V9="Above Avg Pay",W9="High Performer"),"Well Aligned", IF( AND(V9="Below Avg Pay",W9="High Performer"),"Underpaid High Performer", IF( AND(V9="Above Avg Pay",W9="Low/Avg Performer"),"Overpaid Low Performer", "Low Pay & Low Performance" ) ) ) -> Well Aligned | AD9: Underpaid High Performer | AE9: =COUNTIF(Y:Y,"Underpaid High Performer") -> 456
A10: E100008 | B10: M | C10: 34 | D10: Graduate | E10: HR | F10: HR Executive | G10: 43812 | H10: M214 | I10: Mumbai | J10: Full-time | K10: =_xlfn.XLOOKUP(A10,attrition_cleaned!$A:$A,attrition_cleaned!$B:$B,"Missing") -> No | M10: =_xlfn.XLOOKUP(A10,compensation_cleaned!$A:$A,compensation_cleaned!$B:$B,"Missing") -> 418481 | N10: =_xlfn.XLOOKUP(A10,compensation_cleaned!$A:$A,compensation_cleaned!$C:$C,"Missing") -> 38859 | O10: =_xlfn.XLOOKUP(A10,compensation_cleaned!$A:$A,compensation_cleaned!$D:$D,"Missing") -> L1 | P10: =_xlfn.XLOOKUP(A10,engagement_pivot!$A:$A,engagement_pivot!$B:$B,"Missing") -> 2 | Q10: =IF( _xlfn.XLOOKUP(A10, engagement_pivot!A:A, engagement_pivot!C:C, 0) > 0, "Yes", "No" ) -> Yes | R10: =IF(K10="Yes",DATEDIF(G10,L10,"M"),DATEDIF(G10,DATE(2023,12,31),"M")) -> 48 | S10: =IF(R10<=12,"0–12 months", IF(R10<=36,"13–36 months","37+ months")) -> 37+ months | T10: =_xlfn.XLOOKUP(A10,performance_pivot!$A:$A,performance_pivot!$B:$B,"Missing") -> 3.5 | U10: =_xlfn.XLOOKUP(A10,compensation_cleaned!$A:$A,compensation_cleaned!$F:$F,"Missing") -> 499723.04 | V10: =IF(M10>U10,"Above Avg Pay","Below Avg Pay") -> Below Avg Pay | W10: =IF(T10>=4,"High Performer","Low/Avg Performer") -> Low/Avg Performer | Y10: =IF( AND(V10="Above Avg Pay",W10="High Performer"),"Well Aligned", IF( AND(V10="Below Avg Pay",W10="High Performer"),"Underpaid High Performer", IF( AND(V10="Above Avg Pay",W10="Low/Avg Performer"),"Overpaid Low Performer", "Low Pay & Low Performance" ) ) ) -> Low Pay & Low Performance | AD10: Overpaid Low Performer | AE10: =COUNTIF(Y:Y,"Overpaid Low Performer") -> 1230
A11: E100009 | B11: M | C11: 32 | D11: Graduate | E11: IT | F11: Software Engineer | G11: 44763 | H11: M335 | I11: Pune | J11: Full-time | K11: =_xlfn.XLOOKUP(A11,attrition_cleaned!$A:$A,attrition_cleaned!$B:$B,"Missing") -> No | M11: =_xlfn.XLOOKUP(A11,compensation_cleaned!$A:$A,compensation_cleaned!$B:$B,"Missing") -> 757662 | N11: =_xlfn.XLOOKUP(A11,compensation_cleaned!$A:$A,compensation_cleaned!$C:$C,"Missing") -> 97007 | O11: =_xlfn.XLOOKUP(A11,compensation_cleaned!$A:$A,compensation_cleaned!$D:$D,"Missing") -> L2 | P11: =_xlfn.XLOOKUP(A11,engagement_pivot!$A:$A,engagement_pivot!$B:$B,"Missing") -> 3 | Q11: =IF( _xlfn.XLOOKUP(A11, engagement_pivot!A:A, engagement_pivot!C:C, 0) > 0, "Yes", "No" ) -> Yes | R11: =IF(K11="Yes",DATEDIF(G11,L11,"M"),DATEDIF(G11,DATE(2023,12,31),"M")) -> 17 | S11: =IF(R11<=12,"0–12 months", IF(R11<=36,"13–36 months","37+ months")) -> 13–36 months | T11: =_xlfn.XLOOKUP(A11,performance_pivot!$A:$A,performance_pivot!$B:$B,"Missing") -> 4.25 | U11: =_xlfn.XLOOKUP(A11,compensation_cleaned!$A:$A,compensation_cleaned!$F:$F,"Missing") -> 746435.4 | V11: =IF(M11>U11,"Above Avg Pay","Below Avg Pay") -> Above Avg Pay | W11: =IF(T11>=4,"High Performer","Low/Avg Performer") -> High Performer | Y11: =IF( AND(V11="Above Avg Pay",W11="High Performer"),"Well Aligned", IF( AND(V11="Below Avg Pay",W11="High Performer"),"Underpaid High Performer", IF( AND(V11="Above Avg Pay",W11="Low/Avg Performer"),"Overpaid Low Performer", "Low Pay & Low Performance" ) ) ) -> Well Aligned | AD11: Low Pay & Low Performance | AE11: =COUNTIF(Y:Y,"Low Pay & Low Performance") -> 892
A12: E100010 | B12: F | C12: 28 | D12: Postgraduate | E12: Sales | F12: Sales Executive | G12: 45014 | H12: M211 | I12: Hyderabad | J12: Full-time | K12: =_xlfn.XLOOKUP(A12,attrition_cleaned!$A:$A,attrition_cleaned!$B:$B,"Missing") -> No | M12: =_xlfn.XLOOKUP(A12,compensation_cleaned!$A:$A,compensation_cleaned!$B:$B,"Missing") -> 1192590 | N12: =_xlfn.XLOOKUP(A12,compensation_cleaned!$A:$A,compensation_cleaned!$C:$C,"Missing") -> 110531 | O12: =_xlfn.XLOOKUP(A12,compensation_cleaned!$A:$A,compensation_cleaned!$D:$D,"Missing") -> L3 | P12: =_xlfn.XLOOKUP(A12,engagement_pivot!$A:$A,engagement_pivot!$B:$B,"Missing") -> 5 | Q12: =IF( _xlfn.XLOOKUP(A12, engagement_pivot!A:A, engagement_pivot!C:C, 0) > 0, "Yes", "No" ) -> Yes | R12: =IF(K12="Yes",DATEDIF(G12,L12,"M"),DATEDIF(G12,DATE(2023,12,31),"M")) -> 9 | S12: =IF(R12<=12,"0–12 months", IF(R12<=36,"13–36 months","37+ months")) -> 0–12 months | T12: =_xlfn.XLOOKUP(A12,performance_pivot!$A:$A,performance_pivot!$B:$B,"Missing") -> 3 | U12: =_xlfn.XLOOKUP(A12,compensation_cleaned!$A:$A,compensation_cleaned!$F:$F,"Missing") -> 1044648.5 | V12: =IF(M12>U12,"Above Avg Pay","Below Avg Pay") -> Above Avg Pay | W12: =IF(T12>=4,"High Performer","Low/Avg Performer") -> Low/Avg Performer | Y12: =IF( AND(V12="Above Avg Pay",W12="High Performer"),"Well Aligned", IF( AND(V12="Below Avg Pay",W12="High Performer"),"Underpaid High Performer", IF( AND(V12="Above Avg Pay",W12="Low/Avg Performer"),"Overpaid Low Performer", "Low Pay & Low Performance" ) ) ) -> Overpaid Low Performer
A13: E100011 | B13: M | C13: 24 | D13: Graduate | E13: Operations | F13: Operations Analyst | G13: 44631 | H13: M300 | I13: Chennai | J13: Full-time | K13: =_xlfn.XLOOKUP(A13,attrition_cleaned!$A:$A,attrition_cleaned!$B:$B,"Missing") -> No | M13: =_xlfn.XLOOKUP(A13,compensation_cleaned!$A:$A,compensation_cleaned!$B:$B,"Missing") -> 1160686 | N13: =_xlfn.XLOOKUP(A13,compensation_cleaned!$A:$A,compensation_cleaned!$C:$C,"Missing") -> 70987 | O13: =_xlfn.XLOOKUP(A13,compensation_cleaned!$A:$A,compensation_cleaned!$D:$D,"Missing") -> L3 | P13: =_xlfn.XLOOKUP(A13,engagement_pivot!$A:$A,engagement_pivot!$B:$B,"Missing") -> 2.5 | Q13: =IF( _xlfn.XLOOKUP(A13, engagement_pivot!A:A, engagement_pivot!C:C, 0) > 0, "Yes", "No" ) -> Yes | R13: =IF(K13="Yes",DATEDIF(G13,L13,"M"),DATEDIF(G13,DATE(2023,12,31),"M")) -> 21 | S13: =IF(R13<=12,"0–12 months", IF(R13<=36,"13–36 months","37+ months")) -> 13–36 months | T13: =_xlfn.XLOOKUP(A13,performance_pivot!$A:$A,performance_pivot!$B:$B,"Missing") -> 3 | U13: =_xlfn.XLOOKUP(A13,compensation_cleaned!$A:$A,compensation_cleaned!$F:$F,"Missing") -> 1044648.5 | V13: =IF(M13>U13,"Above Avg Pay","Below Avg Pay") -> Above Avg Pay | W13: =IF(T13>=4,"High Performer","Low/Avg Performer") -> Low/Avg Performer | Y13: =IF( AND(V13="Above Avg Pay",W13="High Performer"),"Well Aligned", IF( AND(V13="Below Avg Pay",W13="High Performer"),"Underpaid High Performer", IF( AND(V13="Above Avg Pay",W13="Low/Avg Performer"),"Overpaid Low Performer", "Low Pay & Low Performance" ) ) ) -> Overpaid Low Performer
A14: E100012 | B14: F | C14: 28 | D14: Graduate | E14: Operations | F14: Process Manager | G14: 43238 | H14: M214 | I14: Hyderabad | J14: Full-time | K14: =_xlfn.XLOOKUP(A14,attrition_cleaned!$A:$A,attrition_cleaned!$B:$B,"Missing") -> No | M14: =_xlfn.XLOOKUP(A14,compensation_cleaned!$A:$A,compensation_cleaned!$B:$B,"Missing") -> 1060040 | N14: =_xlfn.XLOOKUP(A14,compensation_cleaned!$A:$A,compensation_cleaned!$C:$C,"Missing") -> 94821 | O14: =_xlfn.XLOOKUP(A14,compensation_cleaned!$A:$A,compensation_cleaned!$D:$D,"Missing") -> L3 | P14: =_xlfn.XLOOKUP(A14,engagement_pivot!$A:$A,engagement_pivot!$B:$B,"Missing") -> 2 | Q14: =IF( _xlfn.XLOOKUP(A14, engagement_pivot!A:A, engagement_pivot!C:C, 0) > 0, "Yes", "No" ) -> Yes | R14: =IF(K14="Yes",DATEDIF(G14,L14,"M"),DATEDIF(G14,DATE(2023,12,31),"M")) -> 67 | S14: =IF(R14<=12,"0–12 months", IF(R14<=36,"13–36 months","37+ months")) -> 37+ months | T14: =_xlfn.XLOOKUP(A14,performance_pivot!$A:$A,performance_pivot!$B:$B,"Missing") -> 3.75 | U14: =_xlfn.XLOOKUP(A14,compensation_cleaned!$A:$A,compensation_cleaned!$F:$F,"Missing") -> 1044648.5 | V14: =IF(M14>U14,"Above Avg Pay","Below Avg Pay") -> Above Avg Pay | W14: =IF(T14>=4,"High Performer","Low/Avg Performer") -> Low/Avg Performer | Y14: =IF( AND(V14="Above Avg Pay",W14="High Performer"),"Well Aligned", IF( AND(V14="Below Avg Pay",W14="High Performer"),"Underpaid High Performer", IF( AND(V14="Above Avg Pay",W14="Low/Avg Performer"),"Overpaid Low Performer", "Low Pay & Low Performance" ) ) ) -> Overpaid Low Performer
A15: E100013 | B15: F | C15: 41 | D15: Graduate | E15: Operations | F15: Operations Analyst | G15: 43599 | H15: M331 | I15: Chennai | J15: Full-time | K15: =_xlfn.XLOOKUP(A15,attrition_cleaned!$A:$A,attrition_cleaned!$B:$B,"Missing") -> No | M15: =_xlfn.XLOOKUP(A15,compensation_cleaned!$A:$A,compensation_cleaned!$B:$B,"Missing") -> 1163414 | N15: =_xlfn.XLOOKUP(A15,compensation_cleaned!$A:$A,compensation_cleaned!$C:$C,"Missing") -> 116603 | O15: =_xlfn.XLOOKUP(A15,compensation_cleaned!$A:$A,compensation_cleaned!$D:$D,"Missing") -> L3 | P15: =_xlfn.XLOOKUP(A15,engagement_pivot!$A:$A,engagement_pivot!$B:$B,"Missing") -> 4 | Q15: =IF( _xlfn.XLOOKUP(A15, engagement_pivot!A:A, engagement_pivot!C:C, 0) > 0, "Yes", "No" ) -> Yes | R15: =IF(K15="Yes",DATEDIF(G15,L15,"M"),DATEDIF(G15,DATE(2023,12,31),"M")) -> 55 | S15: =IF(R15<=12,"0–12 months", IF(R15<=36,"13–36 months","37+ months")) -> 37+ months | T15: =_xlfn.XLOOKUP(A15,performance_pivot!$A:$A,performance_pivot!$B:$B,"Missing") -> 2 | U15: =_xlfn.XLOOKUP(A15,compensation_cleaned!$A:$A,compensation_cleaned!$F:$F,"Missing") -> 1044648.5 | V15: =IF(M15>U15,"Above Avg Pay","Below Avg Pay") -> Above Avg Pay | W15: =IF(T15>=4,"High Performer","Low/Avg Performer") -> Low/Avg Performer | Y15: =IF( AND(V15="Above Avg Pay",W15="High Performer"),"Well Aligned", IF( AND(V15="Below Avg Pay",W15="High Performer"),"Underpaid High Performer", IF( AND(V15="Above Avg Pay",W15="Low/Avg Performer"),"Overpaid Low Performer", "Low Pay & Low Performance" ) ) ) -> Overpaid Low Performer
A16: E100014 | B16: M | C16: 28 | D16: Graduate | E16: Operations | F16: Operations Analyst | G16: 43276 | H16: M285 | I16: Delhi | J16: Contract | K16: =_xlfn.XLOOKUP(A16,attrition_cleaned!$A:$A,attrition_cleaned!$B:$B,"Missing") -> No | M16: =_xlfn.XLOOKUP(A16,compensation_cleaned!$A:$A,compensation_cleaned!$B:$B,"Missing") -> 532901 | N16: =_xlfn.XLOOKUP(A16,compensation_cleaned!$A:$A,compensation_cleaned!$C:$C,"Missing") -> 57968 | O16: =_xlfn.XLOOKUP(A16,compensation_cleaned!$A:$A,compensation_cleaned!$D:$D,"Missing") -> L1 | P16: =_xlfn.XLOOKUP(A16,engagement_pivot!$A:$A,engagement_pivot!$B:$B,"Missing") -> 4.5 | Q16: =IF( _xlfn.XLOOKUP(A16, engagement_pivot!A:A, engagement_pivot!C:C, 0) > 0, "Yes", "No" ) -> Yes | R16: =IF(K16="Yes",DATEDIF(G16,L16,"M"),DATEDIF(G16,DATE(2023,12,31),"M")) -> 66 | S16: =IF(R16<=12,"0–12 months", IF(R16<=36,"13–36 months","37+ months")) -> 37+ months | T16: =_xlfn.XLOOKUP(A16,performance_pivot!$A:$A,performance_pivot!$B:$B,"Missing") -> 3.75 | U16: =_xlfn.XLOOKUP(A16,compensation_cleaned!$A:$A,compensation_cleaned!$F:$F,"Missing") -> 499723.04 | V16: =IF(M16>U16,"Above Avg Pay","Below Avg Pay") -> Above Avg Pay | W16: =IF(T16>=4,"High Performer","Low/Avg Performer") -> Low/Avg Performer | Y16: =IF( AND(V16="Above Avg Pay",W16="High Performer"),"Well Aligned", IF( AND(V16="Below Avg Pay",W16="High Performer"),"Underpaid High Performer", IF( AND(V16="Above Avg Pay",W16="Low/Avg Performer"),"Overpaid Low Performer", "Low Pay & Low Performance" ) ) ) -> Overpaid Low Performer
A17: E100015 | B17: F | C17: 33 | D17: Graduate | E17: Operations | F17: Process Manager | G17: 43531 | H17: M274 | I17: Hyderabad | J17: Full-time | K17: =_xlfn.XLOOKUP(A17,attrition_cleaned!$A:$A,attrition_cleaned!$B:$B,"Missing") -> No | M17: =_xlfn.XLOOKUP(A17,compensation_cleaned!$A:$A,compensation_cleaned!$B:$B,"Missing") -> 422000 | N17: =_xlfn.XLOOKUP(A17,compensation_cleaned!$A:$A,compensation_cleaned!$C:$C,"Missing") -> 29980 | O17: =_xlfn.XLOOKUP(A17,compensation_cleaned!$A:$A,compensation_cleaned!$D:$D,"Missing") -> L1 | P17: =_xlfn.XLOOKUP(A17,engagement_pivot!$A:$A,engagement_pivot!$B:$B,"Missing") -> 3.5 | Q17: =IF( _xlfn.XLOOKUP(A17, engagement_pivot!A:A, engagement_pivot!C:C, 0) > 0, "Yes", "No" ) -> Yes | R17: =IF(K17="Yes",DATEDIF(G17,L17,"M"),DATEDIF(G17,DATE(2023,12,31),"M")) -> 57 | S17: =IF(R17<=12,"0–12 months", IF(R17<=36,"13–36 months","37+ months")) -> 37+ months | T17: =_xlfn.XLOOKUP(A17,performance_pivot!$A:$A,performance_pivot!$B:$B,"Missing") -> 4 | U17: =_xlfn.XLOOKUP(A17,compensation_cleaned!$A:$A,compensation_cleaned!$F:$F,"Missing") -> 499723.04 | V17: =IF(M17>U17,"Above Avg Pay","Below Avg Pay") -> Below Avg Pay | W17: =IF(T17>=4,"High Performer","Low/Avg Performer") -> High Performer | Y17: =IF( AND(V17="Above Avg Pay",W17="High Performer"),"Well Aligned", IF( AND(V17="Below Avg Pay",W17="High Performer"),"Underpaid High Performer", IF( AND(V17="Above Avg Pay",W17="Low/Avg Performer"),"Overpaid Low Performer", "Low Pay & Low Performance" ) ) ) -> Underpaid High Performer
A18: E100016 | B18: M | C18: 41 | D18: Graduate | E18: IT | F18: QA Engineer | G18: 44973 | H18: M202 | I18: Chennai | J18: Full-time | K18: =_xlfn.XLOOKUP(A18,attrition_cleaned!$A:$A,attrition_cleaned!$B:$B,"Missing") -> No | M18: =_xlfn.XLOOKUP(A18,compensation_cleaned!$A:$A,compensation_cleaned!$B:$B,"Missing") -> 747356 | N18: =_xlfn.XLOOKUP(A18,compensation_cleaned!$A:$A,compensation_cleaned!$C:$C,"Missing") -> 104502 | O18: =_xlfn.XLOOKUP(A18,compensation_cleaned!$A:$A,compensation_cleaned!$D:$D,"Missing") -> L2 | P18: =_xlfn.XLOOKUP(A18,engagement_pivot!$A:$A,engagement_pivot!$B:$B,"Missing") -> 3 | Q18: =IF( _xlfn.XLOOKUP(A18, engagement_pivot!A:A, engagement_pivot!C:C, 0) > 0, "Yes", "No" ) -> Yes | R18: =IF(K18="Yes",DATEDIF(G18,L18,"M"),DATEDIF(G18,DATE(2023,12,31),"M")) -> 10 | S18: =IF(R18<=12,"0–12 months", IF(R18<=36,"13–36 months","37+ months")) -> 0–12 months | T18: =_xlfn.XLOOKUP(A18,performance_pivot!$A:$A,performance_pivot!$B:$B,"Missing") -> 4 | U18: =_xlfn.XLOOKUP(A18,compensation_cleaned!$A:$A,compensation_cleaned!$F:$F,"Missing") -> 746435.4 | V18: =IF(M18>U18,"Above Avg Pay","Below Avg Pay") -> Above Avg Pay | W18: =IF(T18>=4,"High Performer","Low/Avg Performer") -> High Performer | Y18: =IF( AND(V18="Above Avg Pay",W18="High Performer"),"Well Aligned", IF( AND(V18="Below Avg Pay",W18="High Performer"),"Underpaid High Performer", IF( AND(V18="Above Avg Pay",W18="Low/Avg Performer"),"Overpaid Low Performer", "Low Pay & Low Performance" ) ) ) -> Well Aligned
A19: E100017 | B19: M | C19: 36 | D19: Graduate | E19: IT | F19: Data Analyst | G19: 43993 | H19: M295 | I19: Bangalore | J19: Full-time | K19: =_xlfn.XLOOKUP(A19,attrition_cleaned!$A:$A,attrition_cleaned!$B:$B,"Missing") -> No | M19: =_xlfn.XLOOKUP(A19,compensation_cleaned!$A:$A,compensation_cleaned!$B:$B,"Missing") -> 1102364 | N19: =_xlfn.XLOOKUP(A19,compensation_cleaned!$A:$A,compensation_cleaned!$C:$C,"Missing") -> 120500 | O19: =_xlfn.XLOOKUP(A19,compensation_cleaned!$A:$A,compensation_cleaned!$D:$D,"Missing") -> L3 | P19: =_xlfn.XLOOKUP(A19,engagement_pivot!$A:$A,engagement_pivot!$B:$B,"Missing") -> 4 | Q19: =IF( _xlfn.XLOOKUP(A19, engagement_pivot!A:A, engagement_pivot!C:C, 0) > 0, "Yes", "No" ) -> Yes | R19: =IF(K19="Yes",DATEDIF(G19,L19,"M"),DATEDIF(G19,DATE(2023,12,31),"M")) -> 42 | S19: =IF(R19<=12,"0–12 months", IF(R19<=36,"13–36 months","37+ months")) -> 37+ months | T19: =_xlfn.XLOOKUP(A19,performance_pivot!$A:$A,performance_pivot!$B:$B,"Missing") -> 4 | U19: =_xlfn.XLOOKUP(A19,compensation_cleaned!$A:$A,compensation_cleaned!$F:$F,"Missing") -> 1044648.5 | V19: =IF(M19>U19,"Above Avg Pay","Below Avg Pay") -> Above Avg Pay | W19: =IF(T19>=4,"High Performer","Low/Avg Performer") -> High Performer | Y19: =IF( AND(V19="Above Avg Pay",W19="High Performer"),"Well Aligned", IF( AND(V19="Below Avg Pay",W19="High Performer"),"Underpaid High Performer", IF( AND(V19="Above Avg Pay",W19="Low/Avg Performer"),"Overpaid Low Performer", "Low Pay & Low Performance" ) ) ) -> Well Aligned
A20: E100018 | B20: M | C20: 28 | D20: Graduate | E20: IT | F20: Data Analyst | G20: 43299 | H20: M312 | I20: Mumbai | J20: Full-time | K20: =_xlfn.XLOOKUP(A20,attrition_cleaned!$A:$A,attrition_cleaned!$B:$B,"Missing") -> No | M20: =_xlfn.XLOOKUP(A20,compensation_cleaned!$A:$A,compensation_cleaned!$B:$B,"Missing") -> 1109204 | N20: =_xlfn.XLOOKUP(A20,compensation_cleaned!$A:$A,compensation_cleaned!$C:$C,"Missing") -> 129090 | O20: =_xlfn.XLOOKUP(A20,compensation_cleaned!$A:$A,compensation_cleaned!$D:$D,"Missing") -> L3 | P20: =_xlfn.XLOOKUP(A20,engagement_pivot!$A:$A,engagement_pivot!$B:$B,"Missing") -> 4 | Q20: =IF( _xlfn.XLOOKUP(A20, engagement_pivot!A:A, engagement_pivot!C:C, 0) > 0, "Yes", "No" ) -> Yes | R20: =IF(K20="Yes",DATEDIF(G20,L20,"M"),DATEDIF(G20,DATE(2023,12,31),"M")) -> 65 | S20: =IF(R20<=12,"0–12 months", IF(R20<=36,"13–36 months","37+ months")) -> 37+ months | T20: =_xlfn.XLOOKUP(A20,performance_pivot!$A:$A,performance_pivot!$B:$B,"Missing") -> 3 | U20: =_xlfn.XLOOKUP(A20,compensation_cleaned!$A:$A,compensation_cleaned!$F:$F,"Missing") -> 1044648.5 | V20: =IF(M20>U20,"Above Avg Pay","Below Avg Pay") -> Above Avg Pay | W20: =IF(T20>=4,"High Performer","Low/Avg Performer") -> Low/Avg Performer | Y20: =IF( AND(V20="Above Avg Pay",W20="High Performer"),"Well Aligned", IF( AND(V20="Below Avg Pay",W20="High Performer"),"Underpaid High Performer", IF( AND(V20="Above Avg Pay",W20="Low/Avg Performer"),"Overpaid Low Performer", "Low Pay & Low Performance" ) ) ) -> Overpaid Low Performer
A21: E100019 | B21: F | C21: 43 | D21: Graduate | E21: IT | F21: QA Engineer | G21: 44896 | H21: M328 | I21: Pune | J21: Full-time | K21: =_xlfn.XLOOKUP(A21,attrition_cleaned!$A:$A,attrition_cleaned!$B:$B,"Missing") -> No | M21: =_xlfn.XLOOKUP(A21,compensation_cleaned!$A:$A,compensation_cleaned!$B:$B,"Missing") -> 574279 | N21: =_xlfn.XLOOKUP(A21,compensation_cleaned!$A:$A,compensation_cleaned!$C:$C,"Missing") -> 46639 | O21: =_xlfn.XLOOKUP(A21,compensation_cleaned!$A:$A,compensation_cleaned!$D:$D,"Missing") -> L1 | P21: =_xlfn.XLOOKUP(A21,engagement_pivot!$A:$A,engagement_pivot!$B:$B,"Missing") -> 1 | Q21: =IF( _xlfn.XLOOKUP(A21, engagement_pivot!A:A, engagement_pivot!C:C, 0) > 0, "Yes", "No" ) -> Yes | R21: =IF(K21="Yes",DATEDIF(G21,L21,"M"),DATEDIF(G21,DATE(2023,12,31),"M")) -> 12 | S21: =IF(R21<=12,"0–12 months", IF(R21<=36,"13–36 months","37+ months")) -> 0–12 months | T21: =_xlfn.XLOOKUP(A21,performance_pivot!$A:$A,performance_pivot!$B:$B,"Missing") -> 3 | U21: =_xlfn.XLOOKUP(A21,compensation_cleaned!$A:$A,compensation_cleaned!$F:$F,"Missing") -> 499723.04 | V21: =IF(M21>U21,"Above Avg Pay","Below Avg Pay") -> Above Avg Pay | W21: =IF(T21>=4,"High Performer","Low/Avg Performer") -> Low/Avg Performer | Y21: =IF( AND(V21="Above Avg Pay",W21="High Performer"),"Well Aligned", IF( AND(V21="Below Avg Pay",W21="High Performer"),"Underpaid High Performer", IF( AND(V21="Above Avg Pay",W21="Low/Avg Performer"),"Overpaid Low Performer", "Low Pay & Low Performance" ) ) ) -> Overpaid Low Performer
A22: E100020 | B22: M | C22: 44 | D22: Postgraduate | E22: Operations | F22: Process Manager | G22: 44431 | H22: M322 | I22: Bangalore | J22: Full-time | K22: =_xlfn.XLOOKUP(A22,attrition_cleaned!$A:$A,attrition_cleaned!$B:$B,"Missing") -> No | M22: =_xlfn.XLOOKUP(A22,compensation_cleaned!$A:$A,compensation_cleaned!$B:$B,"Missing") -> 476531 | N22: =_xlfn.XLOOKUP(A22,compensation_cleaned!$A:$A,compensation_cleaned!$C:$C,"Missing") -> 56986 | O22: =_xlfn.XLOOKUP(A22,compensation_cleaned!$A:$A,compensation_cleaned!$D:$D,"Missing") -> L1 | P22: =_xlfn.XLOOKUP(A22,engagement_pivot!$A:$A,engagement_pivot!$B:$B,"Missing") -> 1.5 | Q22: =IF( _xlfn.XLOOKUP(A22, engagement_pivot!A:A, engagement_pivot!C:C, 0) > 0, "Yes", "No" ) -> Yes | R22: =IF(K22="Yes",DATEDIF(G22,L22,"M"),DATEDIF(G22,DATE(2023,12,31),"M")) -> 28 | S22: =IF(R22<=12,"0–12 months", IF(R22<=36,"13–36 months","37+ months")) -> 13–36 months | T22: =_xlfn.XLOOKUP(A22,performance_pivot!$A:$A,performance_pivot!$B:$B,"Missing") -> 3 | U22: =_xlfn.XLOOKUP(A22,compensation_cleaned!$A:$A,compensation_cleaned!$F:$F,"Missing") -> 499723.04 | V22: =IF(M22>U22,"Above Avg Pay","Below Avg Pay") -> Below Avg Pay | W22: =IF(T22>=4,"High Performer","Low/Avg Performer") -> Low/Avg Performer | Y22: =IF( AND(V22="Above Avg Pay",W22="High Performer"),"Well Aligned", IF( AND(V22="Below Avg Pay",W22="High Performer"),"Underpaid High Performer", IF( AND(V22="Above Avg Pay",W22="Low/Avg Performer"),"Overpaid Low Performer", "Low Pay & Low Performance" ) ) ) -> Low Pay & Low Performance
A23: E100021 | B23: M | C23: 37 | D23: Postgraduate | E23: Operations | F23: Process Manager | G23: 42933 | H23: M323 | I23: Pune | J23: Full-time | K23: =_xlfn.XLOOKUP(A23,attrition_cleaned!$A:$A,attrition_cleaned!$B:$B,"Missing") -> No | M23: =_xlfn.XLOOKUP(A23,compensation_cleaned!$A:$A,compensation_cleaned!$B:$B,"Missing") -> 524971 | N23: =_xlfn.XLOOKUP(A23,compensation_cleaned!$A:$A,compensation_cleaned!$C:$C,"Missing") -> 58749 | O23: =_xlfn.XLOOKUP(A23,compensation_cleaned!$A:$A,compensation_cleaned!$D:$D,"Missing") -> L1 | P23: =_xlfn.XLOOKUP(A23,engagement_pivot!$A:$A,engagement_pivot!$B:$B,"Missing") -> 2.6666667 | Q23: =IF( _xlfn.XLOOKUP(A23, engagement_pivot!A:A, engagement_pivot!C:C, 0) > 0, "Yes", "No" ) -> Yes | R23: =IF(K23="Yes",DATEDIF(G23,L23,"M"),DATEDIF(G23,DATE(2023,12,31),"M")) -> 77 | S23: =IF(R23<=12,"0–12 months", IF(R23<=36,"13–36 months","37+ months")) -> 37+ months | T23: =_xlfn.XLOOKUP(A23,performance_pivot!$A:$A,performance_pivot!$B:$B,"Missing") -> 2.6666667 | U23: =_xlfn.XLOOKUP(A23,compensation_cleaned!$A:$A,compensation_cleaned!$F:$F,"Missing") -> 499723.04 | V23: =IF(M23>U23,"Above Avg Pay","Below Avg Pay") -> Above Avg Pay | W23: =IF(T23>=4,"High Performer","Low/Avg Performer") -> Low/Avg Performer | Y23: =IF( AND(V23="Above Avg Pay",W23="High Performer"),"Well Aligned", IF( AND(V23="Below Avg Pay",W23="High Performer"),"Underpaid High Performer", IF( AND(V23="Above Avg Pay",W23="Low/Avg Performer"),"Overpaid Low Performer", "Low Pay & Low Performance" ) ) ) -> Overpaid Low Performer
A24: E100022 | B24: M | C24: 25 | D24: Graduate | E24: Operations | F24: Operations Analyst | G24: 43395 | H24: M346 | I24: Delhi | J24: Full-time | K24: =_xlfn.XLOOKUP(A24,attrition_cleaned!$A:$A,attrition_cleaned!$B:$B,"Missing") -> Yes | L24: 44899 | M24: =_xlfn.XLOOKUP(A24,compensation_cleaned!$A:$A,compensation_cleaned!$B:$B,"Missing") -> 694503 | N24: =_xlfn.XLOOKUP(A24,compensation_cleaned!$A:$A,compensation_cleaned!$C:$C,"Missing") -> 56111 | O24: =_xlfn.XLOOKUP(A24,compensation_cleaned!$A:$A,compensation_cleaned!$D:$D,"Missing") -> L2 | P24: =_xlfn.XLOOKUP(A24,engagement_pivot!$A:$A,engagement_pivot!$B:$B,"Missing") -> 4 | Q24: =IF( _xlfn.XLOOKUP(A24, engagement_pivot!A:A, engagement_pivot!C:C, 0) > 0, "Yes", "No" ) -> Yes | R24: =IF(K24="Yes",DATEDIF(G24,L24,"M"),DATEDIF(G24,DATE(2023,12,31),"M")) -> 49 | S24: =IF(R24<=12,"0–12 months", IF(R24<=36,"13–36 months","37+ months")) -> 37+ months | T24: =_xlfn.XLOOKUP(A24,performance_pivot!$A:$A,performance_pivot!$B:$B,"Missing") -> 2.3333333 | U24: =_xlfn.XLOOKUP(A24,compensation_cleaned!$A:$A,compensation_cleaned!$F:$F,"Missing") -> 746435.4 | V24: =IF(M24>U24,"Above Avg Pay","Below Avg Pay") -> Below Avg Pay | W24: =IF(T24>=4,"High Performer","Low/Avg Performer") -> Low/Avg Performer | Y24: =IF( AND(V24="Above Avg Pay",W24="High Performer"),"Well Aligned", IF( AND(V24="Below Avg Pay",W24="High Performer"),"Underpaid High Performer", IF( AND(V24="Above Avg Pay",W24="Low/Avg Performer"),"Overpaid Low Performer", "Low Pay & Low Performance" ) ) ) -> Low Pay & Low Performance
A25: E100023 | B25: M | C25: 39 | D25: Postgraduate | E25: Finance | F25: Financial Analyst | G25: 44695 | H25: M210 | I25: Delhi | J25: Full-time | K25: =_xlfn.XLOOKUP(A25,attrition_cleaned!$A:$A,attrition_cleaned!$B:$B,"Missing") -> No | M25: =_xlfn.XLOOKUP(A25,compensation_cleaned!$A:$A,compensation_cleaned!$B:$B,"Missing") -> 637439 | N25: =_xlfn.XLOOKUP(A25,compensation_cleaned!$A:$A,compensation_cleaned!$C:$C,"Missing") -> 69877 | O25: =_xlfn.XLOOKUP(A25,compensation_cleaned!$A:$A,compensation_cleaned!$D:$D,"Missing") -> L2 | P25: =_xlfn.XLOOKUP(A25,engagement_pivot!$A:$A,engagement_pivot!$B:$B,"Missing") -> 4 | Q25: =IF( _xlfn.XLOOKUP(A25, engagement_pivot!A:A, engagement_pivot!C:C, 0) > 0, "Yes", "No" ) -> Yes | R25: =IF(K25="Yes",DATEDIF(G25,L25,"M"),DATEDIF(G25,DATE(2023,12,31),"M")) -> 19 | S25: =IF(R25<=12,"0–12 months", IF(R25<=36,"13–36 months","37+ months")) -> 13–36 months | T25: =_xlfn.XLOOKUP(A25,performance_pivot!$A:$A,performance_pivot!$B:$B,"Missing") -> 3.5 | U25: =_xlfn.XLOOKUP(A25,compensation_cleaned!$A:$A,compensation_cleaned!$F:$F,"Missing") -> 746435.4 | V25: =IF(M25>U25,"Above Avg Pay","Below Avg Pay") -> Below Avg Pay | W25: =IF(T25>=4,"High Performer","Low/Avg Performer") -> Low/Avg Performer | Y25: =IF( AND(V25="Above Avg Pay",W25="High Performer"),"Well Aligned", IF( AND(V25="Below Avg Pay",W25="High Performer"),"Underpaid High Performer", IF( AND(V25="Above Avg Pay",W25="Low/Avg Performer"),"Overpaid Low Performer", "Low Pay & Low Performance" ) ) ) -> Low Pay & Low Performance
A26: E100024 | B26: F | C26: 24 | D26: Graduate | E26: HR | F26: HR Executive | G26: 44174 | H26: M343 | I26: Hyderabad | J26: Contract | K26: =_xlfn.XLOOKUP(A26,attrition_cleaned!$A:$A,attrition_cleaned!$B:$B,"Missing") -> No | M26: =_xlfn.XLOOKUP(A26,compensation_cleaned!$A:$A,compensation_cleaned!$B:$B,"Missing") -> 716079 | N26: =_xlfn.XLOOKUP(A26,compensation_cleaned!$A:$A,compensation_cleaned!$C:$C,"Missing") -> 63086 | O26: =_xlfn.XLOOKUP(A26,compensation_cleaned!$A:$A,compensation_cleaned!$D:$D,"Missing") -> L2 | P26: =_xlfn.XLOOKUP(A26,engagement_pivot!$A:$A,engagement_pivot!$B:$B,"Missing") -> 2.3333333 | Q26: =IF( _xlfn.XLOOKUP(A26, engagement_pivot!A:A, engagement_pivot!C:C, 0) > 0, "Yes", "No" ) -> Yes | R26: =IF(K26="Yes",DATEDIF(G26,L26,"M"),DATEDIF(G26,DATE(2023,12,31),"M")) -> 36 | S26: =IF(R26<=12,"0–12 months", IF(R26<=36,"13–36 months","37+ months")) -> 13–36 months | T26: =_xlfn.XLOOKUP(A26,performance_pivot!$A:$A,performance_pivot!$B:$B,"Missing") -> 3.6666667 | U26: =_xlfn.XLOOKUP(A26,compensation_cleaned!$A:$A,compensation_cleaned!$F:$F,"Missing") -> 746435.4 | V26: =IF(M26>U26,"Above Avg Pay","Below Avg Pay") -> Below Avg Pay | W26: =IF(T26>=4,"High Performer","Low/Avg Performer") -> Low/Avg Performer | Y26: =IF( AND(V26="Above Avg Pay",W26="High Performer"),"Well Aligned", IF( AND(V26="Below Avg Pay",W26="High Performer"),"Underpaid High Performer", IF( AND(V26="Above Avg Pay",W26="Low/Avg Performer"),"Overpaid Low Performer", "Low Pay & Low Performance" ) ) ) -> Low Pay & Low Performance
A27: E100025 | B27: M | C27: 37 | D27: Postgraduate | E27: Finance | F27: Accountant | G27: 43616 | H27: M236 | I27: Pune | J27: Full-time | K27: =_xlfn.XLOOKUP(A27,attrition_cleaned!$A:$A,attrition_cleaned!$B:$B,"Missing") -> Yes | L27: 44569 | M27: =_xlfn.XLOOKUP(A27,compensation_cleaned!$A:$A,compensation_cleaned!$B:$B,"Missing") -> 768411 | N27: =_xlfn.XLOOKUP(A27,compensation_cleaned!$A:$A,compensation_cleaned!$C:$C,"Missing") -> 94536 | O27: =_xlfn.XLOOKUP(A27,compensation_cleaned!$A:$A,compensation_cleaned!$D:$D,"Missing") -> L2 | P27: =_xlfn.XLOOKUP(A27,engagement_pivot!$A:$A,engagement_pivot!$B:$B,"Missing") -> 1 | Q27: =IF( _xlfn.XLOOKUP(A27, engagement_pivot!A:A, engagement_pivot!C:C, 0) > 0, "Yes", "No" ) -> Yes | R27: =IF(K27="Yes",DATEDIF(G27,L27,"M"),DATEDIF(G27,DATE(2023,12,31),"M")) -> 31 | S27: =IF(R27<=12,"0–12 months", IF(R27<=36,"13–36 months","37+ months")) -> 13–36 months | T27: =_xlfn.XLOOKUP(A27,performance_pivot!$A:$A,performance_pivot!$B:$B,"Missing") -> 4 | U27: =_xlfn.XLOOKUP(A27,compensation_cleaned!$A:$A,compensation_cleaned!$F:$F,"Missing") -> 746435.4 | V27: =IF(M27>U27,"Above Avg Pay","Below Avg Pay") -> Above Avg Pay | W27: =IF(T27>=4,"High Performer","Low/Avg Performer") -> High Performer | Y27: =IF( AND(V27="Above Avg Pay",W27="High Performer"),"Well Aligned", IF( AND(V27="Below Avg Pay",W27="High Performer"),"Underpaid High Performer", IF( AND(V27="Above Avg Pay",W27="Low/Avg Performer"),"Overpaid Low Performer", "Low Pay & Low Performance" ) ) ) -> Well Aligned
A28: E100026 | B28: F | C28: 24 | D28: Postgraduate | E28: IT | F28: QA Engineer | G28: 44418 | H28: M253 | I28: Bangalore | J28: Full-time | K28: =_xlfn.XLOOKUP(A28,attrition_cleaned!$A:$A,attrition_cleaned!$B:$B,"Missing") -> No | M28: =_xlfn.XLOOKUP(A28,compensation_cleaned!$A:$A,compensation_cleaned!$B:$B,"Missing") -> 715565 | N28: =_xlfn.XLOOKUP(A28,compensation_cleaned!$A:$A,compensation_cleaned!$C:$C,"Missing") -> 81470 | O28: =_xlfn.XLOOKUP(A28,compensation_cleaned!$A:$A,compensation_cleaned!$D:$D,"Missing") -> L2 | P28: =_xlfn.XLOOKUP(A28,engagement_pivot!$A:$A,engagement_pivot!$B:$B,"Missing") -> 3.5 | Q28: =IF( _xlfn.XLOOKUP(A28, engagement_pivot!A:A, engagement_pivot!C:C, 0) > 0, "Yes", "No" ) -> Yes | R28: =IF(K28="Yes",DATEDIF(G28,L28,"M"),DATEDIF(G28,DATE(2023,12,31),"M")) -> 28 | S28: =IF(R28<=12,"0–12 months", IF(R28<=36,"13–36 months","37+ months")) -> 13–36 months | T28: =_xlfn.XLOOKUP(A28,performance_pivot!$A:$A,performance_pivot!$B:$B,"Missing") -> 4.25 | U28: =_xlfn.XLOOKUP(A28,compensation_cleaned!$A:$A,compensation_cleaned!$F:$F,"Missing") -> 746435.4 | V28: =IF(M28>U28,"Above Avg Pay","Below Avg Pay") -> Below Avg Pay | W28: =IF(T28>=4,"High Performer","Low/Avg Performer") -> High Performer | Y28: =IF( AND(V28="Above Avg Pay",W28="High Performer"),"Well Aligned", IF( AND(V28="Below Avg Pay",W28="High Performer"),"Underpaid High Performer", IF( AND(V28="Above Avg Pay",W28="Low/Avg Performer"),"Overpaid Low Performer", "Low Pay & Low Performance" ) ) ) -> Underpaid High Performer
A29: E100027 | B29: F | C29: 41 | D29: Graduate | E29: Sales | F29: Sales Executive | G29: 44179 | H29: M311 | I29: Chennai | J29: Contract | K29: =_xlfn.XLOOKUP(A29,attrition_cleaned!$A:$A,attrition_cleaned!$B:$B,"Missing") -> No | M29: =_xlfn.XLOOKUP(A29,compensation_cleaned!$A:$A,compensation_cleaned!$B:$B,"Missing") -> 901095 | N29: =_xlfn.XLOOKUP(A29,compensation_cleaned!$A:$A,compensation_cleaned!$C:$C,"Missing") -> 102199 | O29: =_xlfn.XLOOKUP(A29,compensation_cleaned!$A:$A,compensation_cleaned!$D:$D,"Missing") -> L3 | P29: =_xlfn.XLOOKUP(A29,engagement_pivot!$A:$A,engagement_pivot!$B:$B,"Missing") -> 3.5 | Q29: =IF( _xlfn.XLOOKUP(A29, engagement_pivot!A:A, engagement_pivot!C:C, 0) > 0, "Yes", "No" ) -> Yes | R29: =IF(K29="Yes",DATEDIF(G29,L29,"M"),DATEDIF(G29,DATE(2023,12,31),"M")) -> 36 | S29: =IF(R29<=12,"0–12 months", IF(R29<=36,"13–36 months","37+ months")) -> 13–36 months | T29: =_xlfn.XLOOKUP(A29,performance_pivot!$A:$A,performance_pivot!$B:$B,"Missing") -> 2.5 | U29: =_xlfn.XLOOKUP(A29,compensation_cleaned!$A:$A,compensation_cleaned!$F:$F,"Missing") -> 1044648.5 | V29: =IF(M29>U29,"Above Avg Pay","Below Avg Pay") -> Below Avg Pay | W29: =IF(T29>=4,"High Performer","Low/Avg Performer") -> Low/Avg Performer | Y29: =IF( AND(V29="Above Avg Pay",W29="High Performer"),"Well Aligned", IF( AND(V29="Below Avg Pay",W29="High Performer"),"Underpaid High Performer", IF( AND(V29="Above Avg Pay",W29="Low/Avg Performer"),"Overpaid Low Performer", "Low Pay & Low Performance" ) ) ) -> Low Pay & Low Performance
A30: E100028 | B30: M | C30: 23 | D30: Postgraduate | E30: IT | F30: Software Engineer | G30: 44655 | H30: M267 | I30: Bangalore | J30: Full-time | K30: =_xlfn.XLOOKUP(A30,attrition_cleaned!$A:$A,attrition_cleaned!$B:$B,"Missing") -> No | M30: =_xlfn.XLOOKUP(A30,compensation_cleaned!$A:$A,compensation_cleaned!$B:$B,"Missing") -> 1537237 | N30: =_xlfn.XLOOKUP(A30,compensation_cleaned!$A:$A,compensation_cleaned!$C:$C,"Missing") -> 224170 | O30: =_xlfn.XLOOKUP(A30,compensation_cleaned!$A:$A,compensation_cleaned!$D:$D,"Missing") -> L4 | P30: =_xlfn.XLOOKUP(A30,engagement_pivot!$A:$A,engagement_pivot!$B:$B,"Missing") -> 3.5 | Q30: =IF( _xlfn.XLOOKUP(A30, engagement_pivot!A:A, engagement_pivot!C:C, 0) > 0, "Yes", "No" ) -> Yes | R30: =IF(K30="Yes",DATEDIF(G30,L30,"M"),DATEDIF(G30,DATE(2023,12,31),"M")) -> 20 | S30: =IF(R30<=12,"0–12 months", IF(R30<=36,"13–36 months","37+ months")) -> 13–36 months | T30: =_xlfn.XLOOKUP(A30,performance_pivot!$A:$A,performance_pivot!$B:$B,"Missing") -> 3.5 | U30: =_xlfn.XLOOKUP(A30,compensation_cleaned!$A:$A,compensation_cleaned!$F:$F,"Missing") -> 1044648.5 | V30: =IF(M30>U30,"Above Avg Pay","Below Avg Pay") -> Above Avg Pay | W30: =IF(T30>=4,"High Performer","Low/Avg Performer") -> Low/Avg Performer | Y30: =IF( AND(V30="Above Avg Pay",W30="High Performer"),"Well Aligned", IF( AND(V30="Below Avg Pay",W30="High Performer"),"Underpaid High Performer", IF( AND(V30="Above Avg Pay",W30="Low/Avg Performer"),"Overpaid Low Performer", "Low Pay & Low Performance" ) ) ) -> Overpaid Low Performer
A31: E100029 | B31: F | C31: 24 | D31: Postgraduate | E31: Finance | F31: Accountant | G31: 44655 | H31: M232 | I31: Delhi | J31: Full-time | K31: =_xlfn.XLOOKUP(A31,attrition_cleaned!$A:$A,attrition_cleaned!$B:$B,"Missing") -> No | M31: =_xlfn.XLOOKUP(A31,compensation_cleaned!$A:$A,compensation_cleaned!$B:$B,"Missing") -> 1506029 | N31: =_xlfn.XLOOKUP(A31,compensation_cleaned!$A:$A,compensation_cleaned!$C:$C,"Missing") -> 171792 | O31: =_xlfn.XLOOKUP(A31,compensation_cleaned!$A:$A,compensation_cleaned!$D:$D,"Missing") -> L4 | P31: =_xlfn.XLOOKUP(A31,engagement_pivot!$A:$A,engagement_pivot!$B:$B,"Missing") -> 3.3333333 | Q31: =IF( _xlfn.XLOOKUP(A31, engagement_pivot!A:A, engagement_pivot!C:C, 0) > 0, "Yes", "No" ) -> Yes | R31: =IF(K31="Yes",DATEDIF(G31,L31,"M"),DATEDIF(G31,DATE(2023,12,31),"M")) -> 20 | S31: =IF(R31<=12,"0–12 months", IF(R31<=36,"13–36 months","37+ months")) -> 13–36 months | T31: =_xlfn.XLOOKUP(A31,performance_pivot!$A:$A,performance_pivot!$B:$B,"Missing") -> 3.3333333 | U31: =_xlfn.XLOOKUP(A31,compensation_cleaned!$A:$A,compensation_cleaned!$F:$F,"Missing") -> 1044648.5 | V31: =IF(M31>U31,"Above Avg Pay","Below Avg Pay") -> Above Avg Pay | W31: =IF(T31>=4,"High Performer","Low/Avg Performer") -> Low/Avg Performer | Y31: =IF( AND(V31="Above Avg Pay",W31="High Performer"),"Well Aligned", IF( AND(V31="Below Avg Pay",W31="High Performer"),"Underpaid High Performer", IF( AND(V31="Above Avg Pay",W31="Low/Avg Performer"),"Overpaid Low Performer", "Low Pay & Low Performance" ) ) ) -> Overpaid Low Performer
A32: E100030 | B32: F | C32: 23 | D32: Graduate | E32: Operations | F32: Operations Analyst | G32: 45221 | H32: M296 | I32: Delhi | J32: Full-time | K32: =_xlfn.XLOOKUP(A32,attrition_cleaned!$A:$A,attrition_cleaned!$B:$B,"Missing") -> No | M32: =_xlfn.XLOOKUP(A32,compensation_cleaned!$A:$A,compensation_cleaned!$B:$B,"Missing") -> 1330865 | N32: =_xlfn.XLOOKUP(A32,compensation_cleaned!$A:$A,compensation_cleaned!$C:$C,"Missing") -> 86298 | O32: =_xlfn.XLOOKUP(A32,compensation_cleaned!$A:$A,compensation_cleaned!$D:$D,"Missing") -> L4 | P32: =_xlfn.XLOOKUP(A32,engagement_pivot!$A:$A,engagement_pivot!$B:$B,"Missing") -> 5 | Q32: =IF( _xlfn.XLOOKUP(A32, engagement_pivot!A:A, engagement_pivot!C:C, 0) > 0, "Yes", "No" ) -> Yes | R32: =IF(K32="Yes",DATEDIF(G32,L32,"M"),DATEDIF(G32,DATE(2023,12,31),"M")) -> 2 | S32: =IF(R32<=12,"0–12 months", IF(R32<=36,"13–36 months","37+ months")) -> 0–12 months | T32: =_xlfn.XLOOKUP(A32,performance_pivot!$A:$A,performance_pivot!$B:$B,"Missing") -> 3 | U32: =_xlfn.XLOOKUP(A32,compensation_cleaned!$A:$A,compensation_cleaned!$F:$F,"Missing") -> 1044648.5 | V32: =IF(M32>U32,"Above Avg Pay","Below Avg Pay") -> Above Avg Pay | W32: =IF(T32>=4,"High Performer","Low/Avg Performer") -> Low/Avg Performer | Y32: =IF( AND(V32="Above Avg Pay",W32="High Performer"),"Well Aligned", IF( AND(V32="Below Avg Pay",W32="High Performer"),"Underpaid High Performer", IF( AND(V32="Above Avg Pay",W32="Low/Avg Performer"),"Overpaid Low Performer", "Low Pay & Low Performance" ) ) ) -> Overpaid Low Performer
A33: E100031 | B33: M | C33: 24 | D33: Postgraduate | E33: IT | F33: Software Engineer | G33: 43551 | H33: M216 | I33: Delhi | J33: Contract | K33: =_xlfn.XLOOKUP(A33,attrition_cleaned!$A:$A,attrition_cleaned!$B:$B,"Missing") -> Yes | L33: 44718 | M33: =_xlfn.XLOOKUP(A33,compensation_cleaned!$A:$A,compensation_cleaned!$B:$B,"Missing") -> 1214015 | N33: =_xlfn.XLOOKUP(A33,compensation_cleaned!$A:$A,compensation_cleaned!$C:$C,"Missing") -> 135971 | O33: =_xlfn.XLOOKUP(A33,compensation_cleaned!$A:$A,compensation_cleaned!$D:$D,"Missing") -> L4 | P33: =_xlfn.XLOOKUP(A33,engagement_pivot!$A:$A,engagement_pivot!$B:$B,"Missing") -> 3 | Q33: =IF( _xlfn.XLOOKUP(A33, engagement_pivot!A:A, engagement_pivot!C:C, 0) > 0, "Yes", "No" ) -> Yes | R33: =IF(K33="Yes",DATEDIF(G33,L33,"M"),DATEDIF(G33,DATE(2023,12,31),"M")) -> 38 | S33: =IF(R33<=12,"0–12 months", IF(R33<=36,"13–36 months","37+ months")) -> 37+ months | T33: =_xlfn.XLOOKUP(A33,performance_pivot!$A:$A,performance_pivot!$B:$B,"Missing") -> 2.5 | U33: =_xlfn.XLOOKUP(A33,compensation_cleaned!$A:$A,compensation_cleaned!$F:$F,"Missing") -> 1044648.5 | V33: =IF(M33>U33,"Above Avg Pay","Below Avg Pay") -> Above Avg Pay | W33: =IF(T33>=4,"High Performer","Low/Avg Performer") -> Low/Avg Performer | Y33: =IF( AND(V33="Above Avg Pay",W33="High Performer"),"Well Aligned", IF( AND(V33="Below Avg Pay",W33="High Performer"),"Underpaid High Performer", IF( AND(V33="Above Avg Pay",W33="Low/Avg Performer"),"Overpaid Low Performer", "Low Pay & Low Performance" ) ) ) -> Overpaid Low Performer
A34: E100032 | B34: F | C34: 26 | D34: Postgraduate | E34: Operations | F34: Process Manager | G34: 44882 | H34: M245 | I34: Mumbai | J34: Full-time | K34: =_xlfn.XLOOKUP(A34,attrition_cleaned!$A:$A,attrition_cleaned!$B:$B,"Missing") -> Yes | L34: 45226 | M34: =_xlfn.XLOOKUP(A34,compensation_cleaned!$A:$A,compensation_cleaned!$B:$B,"Missing") -> 905850 | N34: =_xlfn.XLOOKUP(A34,compensation_cleaned!$A:$A,compensation_cleaned!$C:$C,"Missing") -> 53220 | O34: =_xlfn.XLOOKUP(A34,compensation_cleaned!$A:$A,compensation_cleaned!$D:$D,"Missing") -> L3 | P34: =_xlfn.XLOOKUP(A34,engagement_pivot!$A:$A,engagement_pivot!$B:$B,"Missing") -> 4 | Q34: =IF( _xlfn.XLOOKUP(A34, engagement_pivot!A:A, engagement_pivot!C:C, 0) > 0, "Yes", "No" ) -> Yes | R34: =IF(K34="Yes",DATEDIF(G34,L34,"M"),DATEDIF(G34,DATE(2023,12,31),"M")) -> 11 | S34: =IF(R34<=12,"0–12 months", IF(R34<=36,"13–36 months","37+ months")) -> 0–12 months | T34: =_xlfn.XLOOKUP(A34,performance_pivot!$A:$A,performance_pivot!$B:$B,"Missing") -> 3.5 | U34: =_xlfn.XLOOKUP(A34,compensation_cleaned!$A:$A,compensation_cleaned!$F:$F,"Missing") -> 1044648.5 | V34: =IF(M34>U34,"Above Avg Pay","Below Avg Pay") -> Below Avg Pay | W34: =IF(T34>=4,"High Performer","Low/Avg Performer") -> Low/Avg Performer | Y34: =IF( AND(V34="Above Avg Pay",W34="High Performer"),"Well Aligned", IF( AND(V34="Below Avg Pay",W34="High Performer"),"Underpaid High Performer", IF( AND(V34="Above Avg Pay",W34="Low/Avg Performer"),"Overpaid Low Performer", "Low Pay & Low Performance" ) ) ) -> Low Pay & Low Performance
A35: E100033 | B35: M | C35: 42 | D35: Graduate | E35: Finance | F35: Financial Analyst | G35: 43875 | H35: M266 | I35: Hyderabad | J35: Full-time | K35: =_xlfn.XLOOKUP(A35,attrition_cleaned!$A:$A,attrition_cleaned!$B:$B,"Missing") -> Yes | L35: 45626 | M35: =_xlfn.XLOOKUP(A35,compensation_cleaned!$A:$A,compensation_cleaned!$B:$B,"Missing") -> 700865 | N35: =_xlfn.XLOOKUP(A35,compensation_cleaned!$A:$A,compensation_cleaned!$C:$C,"Missing") -> 101103 | O35: =_xlfn.XLOOKUP(A35,compensation_cleaned!$A:$A,compensation_cleaned!$D:$D,"Missing") -> L2 | P35: =_xlfn.XLOOKUP(A35,engagement_pivot!$A:$A,engagement_pivot!$B:$B,"Missing") -> 1 | Q35: =IF( _xlfn.XLOOKUP(A35, engagement_pivot!A:A, engagement_pivot!C:C, 0) > 0, "Yes", "No" ) -> Yes | R35: =IF(K35="Yes",DATEDIF(G35,L35,"M"),DATEDIF(G35,DATE(2023,12,31),"M")) -> 57 | S35: =IF(R35<=12,"0–12 months", IF(R35<=36,"13–36 months","37+ months")) -> 37+ months | T35: =_xlfn.XLOOKUP(A35,performance_pivot!$A:$A,performance_pivot!$B:$B,"Missing") -> 3.5 | U35: =_xlfn.XLOOKUP(A35,compensation_cleaned!$A:$A,compensation_cleaned!$F:$F,"Missing") -> 746435.4 | V35: =IF(M35>U35,"Above Avg Pay","Below Avg Pay") -> Below Avg Pay | W35: =IF(T35>=4,"High Performer","Low/Avg Performer") -> Low/Avg Performer | Y35: =IF( AND(V35="Above Avg Pay",W35="High Performer"),"Well Aligned", IF( AND(V35="Below Avg Pay",W35="High Performer"),"Underpaid High Performer", IF( AND(V35="Above Avg Pay",W35="Low/Avg Performer"),"Overpaid Low Performer", "Low Pay & Low Performance" ) ) ) -> Low Pay & Low Performance
A36: E100034 | B36: M | C36: 39 | D36: Graduate | E36: HR | F36: HR Executive | G36: 44631 | H36: M285 | I36: Hyderabad | J36: Full-time | K36: =_xlfn.XLOOKUP(A36,attrition_cleaned!$A:$A,attrition_cleaned!$B:$B,"Missing") -> No | M36: =_xlfn.XLOOKUP(A36,compensation_cleaned!$A:$A,compensation_cleaned!$B:$B,"Missing") -> 499219 | N36: =_xlfn.XLOOKUP(A36,compensation_cleaned!$A:$A,compensation_cleaned!$C:$C,"Missing") -> 52512 | O36: =_xlfn.XLOOKUP(A36,compensation_cleaned!$A:$A,compensation_cleaned!$D:$D,"Missing") -> L1 | P36: =_xlfn.XLOOKUP(A36,engagement_pivot!$A:$A,engagement_pivot!$B:$B,"Missing") -> 3 | Q36: =IF( _xlfn.XLOOKUP(A36, engagement_pivot!A:A, engagement_pivot!C:C, 0) > 0, "Yes", "No" ) -> Yes | R36: =IF(K36="Yes",DATEDIF(G36,L36,"M"),DATEDIF(G36,DATE(2023,12,31),"M")) -> 21 | S36: =IF(R36<=12,"0–12 months", IF(R36<=36,"13–36 months","37+ months")) -> 13–36 months | T36: =_xlfn.XLOOKUP(A36,performance_pivot!$A:$A,performance_pivot!$B:$B,"Missing") -> 3.6666667 | U36: =_xlfn.XLOOKUP(A36,compensation_cleaned!$A:$A,compensation_cleaned!$F:$F,"Missing") -> 499723.04 | V36: =IF(M36>U36,"Above Avg Pay","Below Avg Pay") -> Below Avg Pay | W36: =IF(T36>=4,"High Performer","Low/Avg Performer") -> Low/Avg Performer | Y36: =IF( AND(V36="Above Avg Pay",W36="High Performer"),"Well Aligned", IF( AND(V36="Below Avg Pay",W36="High Performer"),"Underpaid High Performer", IF( AND(V36="Above Avg Pay",W36="Low/Avg Performer"),"Overpaid Low Performer", "Low Pay & Low Performance" ) ) ) -> Low Pay & Low Performance
A37: E100035 | B37: F | C37: 30 | D37: Postgraduate | E37: HR | F37: HR Business Partner | G37: 43520 | H37: M238 | I37: Mumbai | J37: Full-time | K37: =_xlfn.XLOOKUP(A37,attrition_cleaned!$A:$A,attrition_cleaned!$B:$B,"Missing") -> No | M37: =_xlfn.XLOOKUP(A37,compensation_cleaned!$A:$A,compensation_cleaned!$B:$B,"Missing") -> 928965 | N37: =_xlfn.XLOOKUP(A37,compensation_cleaned!$A:$A,compensation_cleaned!$C:$C,"Missing") -> 106238 | O37: =_xlfn.XLOOKUP(A37,compensation_cleaned!$A:$A,compensation_cleaned!$D:$D,"Missing") -> L3 | P37: =_xlfn.XLOOKUP(A37,engagement_pivot!$A:$A,engagement_pivot!$B:$B,"Missing") -> 3.5 | Q37: =IF( _xlfn.XLOOKUP(A37, engagement_pivot!A:A, engagement_pivot!C:C, 0) > 0, "Yes", "No" ) -> Yes | R37: =IF(K37="Yes",DATEDIF(G37,L37,"M"),DATEDIF(G37,DATE(2023,12,31),"M")) -> 58 | S37: =IF(R37<=12,"0–12 months", IF(R37<=36,"13–36 months","37+ months")) -> 37+ months | T37: =_xlfn.XLOOKUP(A37,performance_pivot!$A:$A,performance_pivot!$B:$B,"Missing") -> 4.5 | U37: =_xlfn.XLOOKUP(A37,compensation_cleaned!$A:$A,compensation_cleaned!$F:$F,"Missing") -> 1044648.5 | V37: =IF(M37>U37,"Above Avg Pay","Below Avg Pay") -> Below Avg Pay | W37: =IF(T37>=4,"High Performer","Low/Avg Performer") -> High Performer | Y37: =IF( AND(V37="Above Avg Pay",W37="High Performer"),"Well Aligned", IF( AND(V37="Below Avg Pay",W37="High Performer"),"Underpaid High Performer", IF( AND(V37="Above Avg Pay",W37="Low/Avg Performer"),"Overpaid Low Performer", "Low Pay & Low Performance" ) ) ) -> Underpaid High Performer
A38: E100036 | B38: F | C38: 34 | D38: Graduate | E38: HR | F38: HR Executive | G38: 44577 | H38: M334 | I38: Bangalore | J38: Full-time | K38: =_xlfn.XLOOKUP(A38,attrition_cleaned!$A:$A,attrition_cleaned!$B:$B,"Missing") -> No | M38: =_xlfn.XLOOKUP(A38,compensation_cleaned!$A:$A,compensation_cleaned!$B:$B,"Missing") -> 617133 | N38: =_xlfn.XLOOKUP(A38,compensation_cleaned!$A:$A,compensation_cleaned!$C:$C,"Missing") -> 88207 | O38: =_xlfn.XLOOKUP(A38,compensation_cleaned!$A:$A,compensation_cleaned!$D:$D,"Missing") -> L2 | P38: =_xlfn.XLOOKUP(A38,engagement_pivot!$A:$A,engagement_pivot!$B:$B,"Missing") -> 2.6666667 | Q38: =IF( _xlfn.XLOOKUP(A38, engagement_pivot!A:A, engagement_pivot!C:C, 0) > 0, "Yes", "No" ) -> Yes | R38: =IF(K38="Yes",DATEDIF(G38,L38,"M"),DATEDIF(G38,DATE(2023,12,31),"M")) -> 23 | S38: =IF(R38<=12,"0–12 months", IF(R38<=36,"13–36 months","37+ months")) -> 13–36 months | T38: =_xlfn.XLOOKUP(A38,performance_pivot!$A:$A,performance_pivot!$B:$B,"Missing") -> 2.75 | U38: =_xlfn.XLOOKUP(A38,compensation_cleaned!$A:$A,compensation_cleaned!$F:$F,"Missing") -> 746435.4 | V38: =IF(M38>U38,"Above Avg Pay","Below Avg Pay") -> Below Avg Pay | W38: =IF(T38>=4,"High Performer","Low/Avg Performer") -> Low/Avg Performer | Y38: =IF( AND(V38="Above Avg Pay",W38="High Performer"),"Well Aligned", IF( AND(V38="Below Avg Pay",W38="High Performer"),"Underpaid High Performer", IF( AND(V38="Above Avg Pay",W38="Low/Avg Performer"),"Overpaid Low Performer", "Low Pay & Low Performance" ) ) ) -> Low Pay & Low Performance
A39: E100037 | B39: M | C39: 40 | D39: Graduate | E39: Finance | F39: Financial Analyst | G39: 43135 | H39: M291 | I39: Hyderabad | J39: Full-time | K39: =_xlfn.XLOOKUP(A39,attrition_cleaned!$A:$A,attrition_cleaned!$B:$B,"Missing") -> Yes | L39: 43750 | M39: =_xlfn.XLOOKUP(A39,compensation_cleaned!$A:$A,compensation_cleaned!$B:$B,"Missing") -> 919399 | N39: =_xlfn.XLOOKUP(A39,compensation_cleaned!$A:$A,compensation_cleaned!$C:$C,"Missing") -> 99092 | O39: =_xlfn.XLOOKUP(A39,compensation_cleaned!$A:$A,compensation_cleaned!$D:$D,"Missing") -> L3 | P39: =_xlfn.XLOOKUP(A39,engagement_pivot!$A:$A,engagement_pivot!$B:$B,"Missing") -> 3.5 | Q39: =IF( _xlfn.XLOOKUP(A39, engagement_pivot!A:A, engagement_pivot!C:C, 0) > 0, "Yes", "No" ) -> Yes | R39: =IF(K39="Yes",DATEDIF(G39,L39,"M"),DATEDIF(G39,DATE(2023,12,31),"M")) -> 20 | S39: =IF(R39<=12,"0–12 months", IF(R39<=36,"13–36 months","37+ months")) -> 13–36 months | T39: =_xlfn.XLOOKUP(A39,performance_pivot!$A:$A,performance_pivot!$B:$B,"Missing") -> 4 | U39: =_xlfn.XLOOKUP(A39,compensation_cleaned!$A:$A,compensation_cleaned!$F:$F,"Missing") -> 1044648.5 | V39: =IF(M39>U39,"Above Avg Pay","Below Avg Pay") -> Below Avg Pay | W39: =IF(T39>=4,"High Performer","Low/Avg Performer") -> High Performer | Y39: =IF( AND(V39="Above Avg Pay",W39="High Performer"),"Well Aligned", IF( AND(V39="Below Avg Pay",W39="High Performer"),"Underpaid High Performer", IF( AND(V39="Above Avg Pay",W39="Low/Avg Performer"),"Overpaid Low Performer", "Low Pay & Low Performance" ) ) ) -> Underpaid High Performer
